Workbook

Sheet Sheet1
A1: Material factor (M) | F1: Vulnerability score
A2: concrete | B2: factor | C2: =0.6 -> 0.6 | D2: - | F2: V = M x(1- h_floor/h_max) x P
A3: masonry | B3: factor | C3: =0.75 -> 0.75 | D3: - | J3: V
A4: timber | B4: factor | C4: =1 -> 1 | D4: - | G4: concrete | H4: low | J4: =C2 * (1- C9/0.5) * C28 -> 0.54 | K4: =J4*0.85 -> 0.459 | L4: <-- plastered
G5: concrete | H5: medium | J5: =C2 * (1- C10/0.5) * C28 -> 0.42 | K5: =J5 * 0.85 -> 0.357 | L5: <-- plastered
A6: Height factor (H) | G6: concrete | H6: high | J6: =C2 * (1- C11/0.5) * C28 -> 0.3 | K6: =J6 * 0.85 -> 0.255 | L6: <-- plastered
A7: h_max | C7: =0.35 -> 0.35 | D7: m | G7: masonry | H7: low | J7: =C3 * (1- C9/0.5) * C28 -> 0.675 | K7: =J7 *0.85 -> 0.57375 | L7: <-- plastered
A8: h_water | C8: 0.23 | D8: m | G8: masonry | H8: low | I8: tile protection | J8: =C3 * (1- C9/0.5) * C27 -> 0.3375
A9: h_floor | B9: low | C9: 0.05 | D9: m | G9: masonry | H9: medium | J9: =C3 * (1- C10/0.5) * C28 -> 0.525 | K9: =J9 * 0.85 -> 0.44625 | L9: <-- plastered
B10: medium | C10: 0.15 | D10: m | G10: masonry | H10: medium | I10: tile protection | J10: =C3 * (1- C10/0.5) * C27 -> 0.2625
B11: high | C11: 0.25 | D11: m | G11: masonry | H11: high | J11: =C3 * (1- C11/0.5) * C28 -> 0.375 | K11: =J11 * 0.85 -> 0.31875 | L11: <-- plastered
A12: h_eff | B12: low | C12: =C8 - C9 -> 0.18 | D12: 0 | E12: m | G12: masonry | H12: high | I12: tile protection | J12: =C3 * (1- C11/0.5) * C27 -> 0.1875
B13: medium | C13: =C8-C10 -> 0.08 | D13: 0 | E13: m | G13: timber | H13: low | J13: =C4 * (1- C9/0.5) * C28 -> 0.9
B14: high | C14: =C8-C11 -> -0.02 | D14: 0 | E14: m | G14: timber | H14: medium | J14: =C4 * (1- C10/0.5) * C28 -> 0.7
A15: height factor | B15: low | C15: =((MAX(C12, D12))/C7) -> 0.51428571 | D15: - | G15: timber | H15: high | J15: =C4 * (1- C11/0.5) * C28 -> 0.5
B16: medium | C16: =((MAX(C13, D13))/C7) -> 0.22857143 | D16: -
B17: high | C17: =((MAX(C14, D14))/C7) -> 0 | D17: - | F17: Hazard score
F18: HZ = 0.7 x (h_water / h_max) + 0.3 x (t / t_max)^2
A19: Time factor (T) | H19: h_water | I19: t | N19: L | O19: M | P19: H | Q19: L | R19: M | S19: H | T19: H-factors | X19: T-factor
A20: t_max | C20: =I30 -> 26.4 | D20: hours | G20: cluster 1 | H20: 0.055 | I20: 4.84 | J20: =0.7 * (H20/H30) + 0.3 * (I20/I30)^2 -> 0.10931014 | N20: =H20 - $C$9 -> 0.005 | O20: =H20 - $C$10 -> -0.095 | P20: =H20 - $C$11 -> -0.195 | Q20: =MAX(N20,0) -> 0.005 | R20: =MAX(O20,0) -> 0 | S20: =MAX(P20,0) -> 0 | T20: =(Q20/H$30) -> 0.012886598 | U20: =(R20/H$30) -> 0 | V20: =(S20/H$30) -> 0 | W20: =I20/I$30 -> 0.18333333 | X20: =W20^2 -> 0.033611111 | Y20: 0.1
A21: t | C21: 10 | D21: hours | G21: cluster 2 | H21: 0.127 | I21: 7.61 | J21: =0.7 * (H21/H$30) + 0.3 * (I21/I$30)^2 -> 0.25405144 | N21: =H21 - $C$9 -> 0.077 | O21: =H21 - $C$10 -> -0.023 | P21: =H21 - $C$11 -> -0.123 | Q21: =MAX(N21,0) -> 0.077 | R21: =MAX(O21,0) -> 0 | S21: =MAX(P21,0) -> 0 | T21: =(Q21/H$30) -> 0.19845361 | U21: =(R21/H$30) -> 0 | V21: =(S21/H$30) -> 0 | W21: =I21/I$30 -> 0.28825758 | X21: =W21^2 -> 0.08309243
A22: time factor | C22: =(C21/C20)^2 -> 0.14348026 | G22: cluster 3 | H22: 0.145 | I22: 12.1 | J22: =0.7 * (H22/H$30) + 0.3 * (I22/I$30)^2 -> 0.32461877 | N22: =H22 - $C$9 -> 0.095 | O22: =H22 - $C$10 -> -0.005 | P22: =H22 - $C$11 -> -0.105 | Q22: =MAX(N22,0) -> 0.095 | R22: =MAX(O22,0) -> 0 | S22: =MAX(P22,0) -> 0 | T22: =(Q22/H$30) -> 0.24484536 | U22: =(R22/H$30) -> 0 | V22: =(S22/H$30) -> 0 | W22: =I22/I$30 -> 0.45833333 | X22: =W22^2 -> 0.21006944
G23: cluster 4 | H23: 0.251 | I23: 9.71 | J23: =0.7 * (H23/H$30) + 0.3 * (I23/I$30)^2 -> 0.49341877 | N23: =H23 - $C$9 -> 0.201 | O23: =H23 - $C$10 -> 0.101 | P23: =H23 - $C$11 -> 0.001 | Q23: =MAX(N23,0) -> 0.201 | R23: =MAX(O23,0) -> 0.101 | S23: =MAX(P23,0) -> 0.001 | T23: =(Q23/H$30) -> 0.51804124 | U23: =(R23/H$30) -> 0.26030928 | V23: =(S23/H$30) -> 0.0025773196 | W23: =I23/I$30 -> 0.36780303 | X23: =W23^2 -> 0.13527907
A24: Protection factor (P) | G24: cluster 5 | H24: 0.171 | I24: 16.2 | J24: =0.7 * (H24/H$30) + 0.3 * (I24/I$30)^2 -> 0.42147003 | N24: =H24 - $C$9 -> 0.121 | O24: =H24 - $C$10 -> 0.021 | P24: =H24 - $C$11 -> -0.079 | Q24: =MAX(N24,0) -> 0.121 | R24: =MAX(O24,0) -> 0.021 | S24: =MAX(P24,0) -> 0 | T24: =(Q24/H$30) -> 0.31185567 | U24: =(R24/H$30) -> 0.054123711 | V24: =(S24/H$30) -> 0 | W24: =I24/I$30 -> 0.61363636 | X24: =W24^2 -> 0.37654959
A25: masonry factor | C25: =0.75 -> 0.75 | D25: - | G25: cluster 6 | H25: 0.157 | I25: 20.7 | J25: =0.7 * (H25/H$30) + 0.3 * (I25/I$30)^2 -> 0.46768699 | N25: =H25 - $C$9 -> 0.107 | O25: =H25 - $C$10 -> 0.007 | P25: =H25 - $C$11 -> -0.093 | Q25: =MAX(N25,0) -> 0.107 | R25: =MAX(O25,0) -> 0.007 | S25: =MAX(P25,0) -> 0 | T25: =(Q25/H$30) -> 0.2757732 | U25: =(R25/H$30) -> 0.018041237 | V25: =(S25/H$30) -> 0 | W25: =I25/I$30 -> 0.78409091 | X25: =W25^2 -> 0.61479855
A26: concrete factor | C26: =0.6 -> 0.6 | D26: - | G26: cluster 7 | H26: 0.204 | I26: 24.3 | J26: =0.7 * (H26/H$30) + 0.3 * (I26/I$30)^2 -> 0.62221221 | N26: =H26 - $C$9 -> 0.154 | O26: =H26 - $C$10 -> 0.054 | P26: =H26 - $C$11 -> -0.046 | Q26: =MAX(N26,0) -> 0.154 | R26: =MAX(O26,0) -> 0.054 | S26: =MAX(P26,0) -> 0 | T26: =(Q26/H$30) -> 0.39690722 | U26: =(R26/H$30) -> 0.13917526 | V26: =(S26/H$30) -> 0 | W26: =I26/I$30 -> 0.92045455 | X26: =W26^2 -> 0.84723657
A27: tile factor | C27: =0.5 -> 0.5 | D27: - | G27: cluster 8 | H27: 0.388 | I27: 12.4 | J27: =0.7 * (H27/H$30) + 0.3 * (I27/I$30)^2 -> 0.76618457 | N27: =H27 - $C$9 -> 0.338 | O27: =H27 - $C$10 -> 0.238 | P27: =H27 - $C$11 -> 0.138 | Q27: =MAX(N27,0) -> 0.338 | R27: =MAX(O27,0) -> 0.238 | S27: =MAX(P27,0) -> 0.138 | T27: =(Q27/H$30) -> 0.87113402 | U27: =(R27/H$30) -> 0.61340206 | V27: =(S27/H$30) -> 0.3556701 | W27: =I27/I$30 -> 0.46969697 | X27: =W27^2 -> 0.22061524
A28: no protection | C28: =1 -> 1 | D28: - | G28: cluster 9 | H28: 0.296 | I28: 18.7 | J28: =0.7 * (H28/H$30) + 0.3 * (I28/I$30)^2 -> 0.68454145 | N28: =H28 - $C$9 -> 0.246 | O28: =H28 - $C$10 -> 0.146 | P28: =H28 - $C$11 -> 0.046 | Q28: =MAX(N28,0) -> 0.246 | R28: =MAX(O28,0) -> 0.146 | S28: =MAX(P28,0) -> 0.046 | T28: =(Q28/H$30) -> 0.63402062 | U28: =(R28/H$30) -> 0.37628866 | V28: =(S28/H$30) -> 0.1185567 | W28: =I28/I$30 -> 0.70833333 | X28: =W28^2 -> 0.50173611
A29: plastered | C29: 0.85 | G29: cluster 10 | H29: 0.352 | I29: 26.4 | J29: =0.7 * (H29/H$30) + 0.3 * (I29/I$30)^2 -> 0.93505155 | N29: =H29 - $C$9 -> 0.302 | O29: =H29 - $C$10 -> 0.202 | P29: =H29 - $C$11 -> 0.102 | Q29: =MAX(N29,0) -> 0.302 | R29: =MAX(O29,0) -> 0.202 | S29: =MAX(P29,0) -> 0.102 | T29: =(Q29/H$30) -> 0.77835052 | U29: =(R29/H$30) -> 0.52061856 | V29: =(S29/H$30) -> 0.2628866 | W29: =I29/I$30 -> 1 | X29: =W29^2 -> 1
H30: =MAX(H20:H29) -> 0.388 | I30: =MAX(I20:I29) -> 26.4
F33: Damage score
F34: D = M x (0.7 x H + 0.3 x T) x P
G39: cluster 1 | H39: =IF(T$20 >0,$C$4 * (0.7 * T$20 + 0.3 * $X$20) * $C$28, 0) -> 0.019103952 | I39: =IF(U20>0, $C$4 * (0.7 * U$20 + 0.3 * $X$20) * $C$28, $Y$20 * $X$20) -> 0.0033611111 | J39: =IF(V20>0, $C$4 * (0.7 * V$20 + 0.3 * $X$20) * $C$28, $Y$20 * $X$20) -> 0.0033611111 | L39: TL | M39: TM | N39: TH
H40: =IF(T20>0, C$4 * (0.7 * T$20 + 0.3 * X$20) * C$26, 0) -> 0.011462371 | I40: =IF(U20>0,$C$4 * (0.7 * U$20 + 0.3 * $X$20) * $C$26, $Y$20 * $X$20) -> 0.0033611111 | J40: =IF(V20>0, $C$4 * (0.7 * V$20 + 0.3 * $X$20) * $C$26, $Y$20 * $X$20) -> 0.0033611111 | L40: TLC | M40: TMC | N40: THC
H41: =IF(T20>0, C$4 * (0.7 * T$20 + 0.3 * X$20) * C$25, 0) -> 0.014327964 | I41: =IF(U20>0, $C$4 * (0.7 * U$20 + 0.3 * $X$20) * $C$25, $Y$20 * $X$20) -> 0.0033611111 | J41: =IF(V20>0, $C$4 * (0.7 * V$20 + 0.3 * $X$20) * $C$25, $Y$20 * $X$20) -> 0.0033611111 | L41: TLM | M41: TMM | N41: THM
H42: =IF(T20>0, C$2 * (0.7 * T$20 + 0.3 * X$20) * C$28, 0) -> 0.011462371 | I42: =IF(U20>0,$C$2 * (0.7 * U$20 + 0.3 * $X$20) * $C$28, $Y$20 * $X$20) -> 0.0033611111 | J42: =IF(V20>0, $C$2 * (0.7 * V$20 + 0.3 * $X$20) * $C$28, $Y$20 * $X$20) -> 0.0033611111 | L42: CL | M42: CM | N42: CH
H43: =IF(T20>0, C$2 * (0.7 * T$20 + 0.3 * X$20) * C$29, 0) -> 0.0097430155 | I43: =IF(U20>0, $C$2 * (0.7 * U$20 + 0.3 * $X$20) * $C$29, $Y$20 * $X$20) -> 0.0033611111 | J43: =IF(V20>0, $C$2 * (0.7 * V$20 + 0.3 * $X$20) * $C$29, $Y$20 * $X$20) -> 0.0033611111 | L43: CLP | M43: CMP | N43: CHP
H44: =IF(T20>0, C$3 * (0.7 * T$20 + 0.3 * X$20) * C$28, 0) -> 0.014327964 | I44: =IF(U20>0, $C$3 * (0.7 * U$20 + 0.3 * $X$20) * $C$28, $Y$20 * $X$20) -> 0.0033611111 | J44: =IF(V20>0, $C$3 * (0.7 * V$20 + 0.3 * $X$20) * $C$28, $Y$20 * $X$20) -> 0.0033611111 | L44: ML | M44: MM | N44: MH
H45: =IF(T20 > 0, C$3 * (0.7 * T$20 + 0.3 * X$20) * C$27, 0) -> 0.007163982 | I45: =IF(U20>0, $C$3 * (0.7 * U$20 + 0.3 * $X$20) * $C$27,$Y$20 * $X$20) -> 0.0033611111 | J45: =IF(V20>0, $C$3 * (0.7 * V$20 + 0.3 * $X$20) * $C$27, $Y$20 * $X$20) -> 0.0033611111 | L45: MLT | M45: MMT | N45: MHT
H46: =IF(T20>0, C$3 * (0.7 * T$20 + 0.3 * X$20) * C$29, 0) -> 0.012178769 | I46: =IF(U20>0, $C$3 * (0.7 * U$20 + 0.3 * $X$20) * $C$29,$Y$20 * $X$20) -> 0.0033611111 | J46: =IF(V20>0, $C$3 * (0.7 * V$20 + 0.3 * $X$20) * $C$29, $Y$20 * $X$20) -> 0.0033611111 | L46: MLP | M46: MMP | N46: MHP
...

Sheet cluster1
C10: =Sheet1!H39 -> 0.019103952 | F10: =Sheet1!I39 -> 0.0033611111 | I10: =Sheet1!J39 -> 0.0033611111
C12: =Sheet1!H40 -> 0.011462371 | F12: =Sheet1!I40 -> 0.0033611111 | I12: =Sheet1!J40 -> 0.0033611111
C14: =Sheet1!H41 -> 0.014327964 | F14: =Sheet1!I41 -> 0.0033611111 | I14: =Sheet1!J41 -> 0.0033611111
C22: =Sheet1!H42 -> 0.011462371 | D22: =Sheet1!H43 -> 0.0097430155 | F22: =Sheet1!I42 -> 0.0033611111 | G22: =Sheet1!I43 -> 0.0033611111 | I22: =Sheet1!J42 -> 0.0033611111 | J22: =Sheet1!J43 -> 0.0033611111
C29: =Sheet1!H44 -> 0.014327964 | D29: =Sheet1!H46 -> 0.012178769 | F29: =Sheet1!I44 -> 0.0033611111 | G29: =Sheet1!I46 -> 0.0033611111 | I29: =Sheet1!J44 -> 0.0033611111 | J29: =Sheet1!J46 -> 0.0033611111
C31: =Sheet1!H45 -> 0.007163982 | F31: =Sheet1!I45 -> 0.0033611111 | I31: =Sheet1!J45 -> 0.0033611111

Sheet cluster2
C10: =Sheet1!H48 -> 0.16384525 | F10: =Sheet1!I48 -> 0.008309243 | I10: =Sheet1!J48 -> 0.008309243
C12: =Sheet1!H49 -> 0.098307153 | F12: =Sheet1!I49 -> 0.008309243 | I12: =Sheet1!J49 -> 0.008309243
C14: =Sheet1!H50 -> 0.12288394 | F14: =Sheet1!I50 -> 0.008309243 | I14: =Sheet1!J50 -> 0.008309243
C22: =Sheet1!H51 -> 0.098307153 | D22: =Sheet1!H52 -> 0.08356108 | F22: =Sheet1!I51 -> 0.008309243 | G22: =Sheet1!I52 -> 0.008309243 | I22: =Sheet1!J51 -> 0.008309243 | J22: =Sheet1!J52 -> 0.008309243
C29: =Sheet1!H53 -> 0.12288394 | D29: =Sheet1!H55 -> 0.10445135 | F29: =Sheet1!I53 -> 0.008309243 | G29: =Sheet1!I55 -> 0 | I29: =Sheet1!J53 -> 0.008309243 | J29: =Sheet1!J55 -> 0.008309243
C31: =Sheet1!H54 -> 0.061441971 | F31: =Sheet1!I54 -> 0.008309243 | I31: =Sheet1!J54 -> 0.008309243

Sheet cluster3
C10: =Sheet1!H57 -> 0.23441259 | F10: =Sheet1!I57 -> 0.021006944 | I10: =Sheet1!J57 -> 0.021006944
C12: =Sheet1!H58 -> 0.14064755 | F12: =Sheet1!I58 -> 0.021006944 | I12: =Sheet1!J58 -> 0.021006944
C14: =Sheet1!H59 -> 0.17580944 | F14: =Sheet1!I59 -> 0.021006944 | I14: =Sheet1!J59 -> 0.021006944
C22: =Sheet1!H60 -> 0.14064755 | D22: =Sheet1!H61 -> 0.11955042 | F22: =Sheet1!I60 -> 0.021006944 | G22: =Sheet1!I61 -> 0.021006944 | I22: =Sheet1!J60 -> 0.021006944 | J22: =Sheet1!J61 -> 0.021006944
C29: =Sheet1!H62 -> 0.17580944 | D29: =Sheet1!H64 -> 0.14943802 | F29: =Sheet1!I62 -> 0.021006944 | G29: =Sheet1!I64 -> 0.021006944 | I29: =Sheet1!J62 -> 0.021006944 | J29: =Sheet1!J63 -> 0.021006944
C31: =Sheet1!H63 -> 0.08790472 | F31: =Sheet1!I63 -> 0.021006944 | I31: =Sheet1!J64 -> 0.021006944

Sheet cluster4
C10: =Sheet1!H66 -> 0.40321259 | F10: =Sheet1!I66 -> 0.22280022 | I10: =Sheet1!J66 -> 0.042387844
C12: =Sheet1!H67 -> 0.24192755 | F12: =Sheet1!I67 -> 0.13368013 | I12: =Sheet1!J67 -> 0.025432707
C14: =Sheet1!H68 -> 0.30240944 | F14: =Sheet1!I68 -> 0.16710016 | I14: =Sheet1!J68 -> 0.031790883
C22: =Sheet1!H69 -> 0.24192755 | D22: =Sheet1!H70 -> 0.20563842 | F22: =Sheet1!I69 -> 0.13368013 | G22: =Sheet1!I70 -> 0.11362811 | I22: =Sheet1!J69 -> 0.025432707 | J22: =Sheet1!J70 -> 0.021617801
C29: =Sheet1!H71 -> 0.30240944 | D29: =Sheet1!H73 -> 0.25704802 | F29: =Sheet1!I71 -> 0.16710016 | G29: =Sheet1!I73 -> 0.14203514 | I29: =Sheet1!J71 -> 0.031790883 | J29: =Sheet1!J73 -> 0.027022251
C31: =Sheet1!H72 -> 0.15120472 | F31: =Sheet1!I72 -> 0.083550081 | I31: =Sheet1!J72 -> 0.015895442

Sheet cluster5
C10: =Sheet1!H75 -> 0.33126385 | F10: =Sheet1!I75 -> 0.15085147 | I10: =Sheet1!J75 -> 0.037654959
C12: =Sheet1!H76 -> 0.19875831 | F12: =Sheet1!I76 -> 0.090510884 | I12: =Sheet1!J76 -> 0.037654959
C14: =Sheet1!H77 -> 0.24844788 | F14: =Sheet1!I77 -> 0.11313861 | I14: =Sheet1!J77 -> 0.037654959
C22: =Sheet1!H78 -> 0.19875831 | D22: =Sheet1!H79 -> 0.16894456 | F22: =Sheet1!I78 -> 0.090510884 | G22: =Sheet1!I79 -> 0.076934252 | I22: =Sheet1!J78 -> 0.037654959 | J22: =Sheet1!J79 -> 0.037654959
C29: =Sheet1!H80 -> 0.24844788 | D29: =Sheet1!H82 -> 0.2111807 | F29: =Sheet1!I80 -> 0.11313861 | G29: =Sheet1!I82 -> 0.096167815 | I29: =Sheet1!J80 -> 0.037654959 | J29: =Sheet1!J82 -> 0.037654959
C31: =Sheet1!H81 -> 0.12422394 | F31: =Sheet1!I81 -> 0.056569303 | I31: =Sheet1!J81 -> 0.037654959

Sheet cluster6
C10: =Sheet1!H84 -> 0.3774808 | F10: =Sheet1!I84 -> 0.19706843 | I10: =Sheet1!J84 -> 0.061479855
C12: =Sheet1!H85 -> 0.22648848 | F12: =Sheet1!I85 -> 0.11824106 | I12: =Sheet1!J85 -> 0.061479855
C14: =Sheet1!H86 -> 0.2831106 | F14: =Sheet1!I86 -> 0.14780132 | I14: =Sheet1!J86 -> 0.061479855
C22: =Sheet1!H87 -> 0.22648848 | D22: =Sheet1!H88 -> 0.19251521 | F22: =Sheet1!I87 -> 0.11824106 | G22: =Sheet1!I88 -> 0.1005049 | I22: =Sheet1!J87 -> 0.061479855 | J22: =Sheet1!J88 -> 0.061479855
C29: =Sheet1!H89 -> 0.2831106 | D29: =Sheet1!H91 -> 0.24064401 | F29: =Sheet1!I89 -> 0.14780132 | G29: =Sheet1!I91 -> 0.12563113 | I29: =Sheet1!J89 -> 0.061479855 | J29: =Sheet1!J91 -> 0.061479855
C31: =Sheet1!H90 -> 0.1415553 | F31: =Sheet1!I90 -> 0.073900662 | I31: =Sheet1!J90 -> 0.061479855

Sheet cluster7
C10: =Sheet1!H93 -> 0.53200602 | F10: =Sheet1!I93 -> 0.35159365 | I10: =Sheet1!J93 -> 0.084723657
C12: =Sheet1!H94 -> 0.31920361 | F12: =Sheet1!I94 -> 0.21095619 | I12: =Sheet1!J94 -> 0.084723657
C14: =Sheet1!H95 -> 0.39900452 | F14: =Sheet1!I95 -> 0.26369524 | I14: =Sheet1!J95 -> 0.084723657
C22: =Sheet1!H96 -> 0.31920361 | D22: =Sheet1!H97 -> 0.27132307 | F22: =Sheet1!I96 -> 0.21095619 | G22: =Sheet1!I97 -> 0.17931276 | I22: =Sheet1!J96 -> 0.084723657 | J22: =Sheet1!J97 -> 0.084723657
C29: =Sheet1!H98 -> 0.39900452 | D29: =Sheet1!H100 -> 0.33915384 | F29: =Sheet1!I98 -> 0.26369524 | G29: =Sheet1!I100 -> 0.22414095 | I29: =Sheet1!J98 -> 0.084723657 | J29: =Sheet1!J100 -> 0.084723657
C31: =Sheet1!H99 -> 0.19950226 | F31: =Sheet1!I99 -> 0.13184762 | I31: =Sheet1!J99 -> 0.084723657

Sheet cluster8
C10: =Sheet1!H102 -> 0.67597839 | F10: =Sheet1!I102 -> 0.49556602 | I10: =Sheet1!J102 -> 0.31515365
C12: =Sheet1!H103 -> 0.40558703 | F12: =Sheet1!I103 -> 0.29733961 | I12: =Sheet1!J103 -> 0.18909219
C14: =Sheet1!H104 -> 0.50698379 | F14: =Sheet1!I104 -> 0.37167451 | I14: =Sheet1!J104 -> 0.23636523
C22: =Sheet1!H105 -> 0.40558703 | D22: =Sheet1!H106 -> 0.34474898 | F22: =Sheet1!I105 -> 0.29733961 | G22: =Sheet1!I106 -> 0.25273867 | I22: =Sheet1!J105 -> 0.18909219 | J22: =Sheet1!J106 -> 0.16072836
C29: =Sheet1!H107 -> 0.50698379 | D29: =Sheet1!H109 -> 0.43093622 | F29: =Sheet1!I107 -> 0.37167451 | G29: =Sheet1!I109 -> 0.31592334 | I29: =Sheet1!J107 -> 0.23636523 | J29: =Sheet1!J109 -> 0.20091045
C31: =Sheet1!H108 -> 0.2534919 | F31: =Sheet1!I108 -> 0.18583726 | I31: =Sheet1!J108 -> 0.11818262

Sheet cluster9
C9: =Sheet1!H111 -> 0.59433527 | F9: =Sheet1!I111 -> 0.4139229 | I9: =Sheet1!J111 -> 0.23351052
C11: =Sheet1!H112 -> 0.26628866 | F11: =Sheet1!I112 -> 0.15804124 | I11: =Sheet1!J112 -> 0.14010631
C13: =Sheet1!H113 -> 0.44575145 | F13: =Sheet1!I113 -> 0.31044217 | I13: =Sheet1!J113 -> 0.17513289
C21: =Sheet1!H114 -> 0.35660116 | D21: =Sheet1!H114 -> 0.35660116 | F21: =Sheet1!I114 -> 0.24835374 | G21: =Sheet1!I115 -> 0.21110068 | I21: =Sheet1!J114 -> 0.14010631 | J21: =Sheet1!J115 -> 0.11909037
C28: =Sheet1!H116 -> 0.44575145 | D28: =Sheet1!H118 -> 0.37888873 | F28: =Sheet1!I116 -> 0.31044217 | G28: =Sheet1!I116 -> 0.31044217 | I28: =Sheet1!J116 -> 0.17513289 | J28: =Sheet1!J118 -> 0.14886296
C30: =Sheet1!H117 -> 0.22287572 | F30: =Sheet1!I117 -> 0.15522109 | I30: =Sheet1!J117 -> 0.087566447

Sheet cluster10
C9: =Sheet1!H120 -> 0.84484536 | F9: =Sheet1!I120 -> 0.66443299 | I9: =Sheet1!J120 -> 0.48402062
C11: =Sheet1!H121 -> 0.50690722 | F11: =Sheet1!I121 -> 0.39865979 | I11: =Sheet1!J121 -> 0.29041237
C13: =Sheet1!H122 -> 0.63363402 | F13: =Sheet1!I122 -> 0.49832474 | I13: =Sheet1!J122 -> 0.36301546
C21: =Sheet1!H123 -> 0.50690722 | D21: =Sheet1!H124 -> 0.43087113 | F21: =Sheet1!I123 -> 0.39865979 | G21: =Sheet1!I124 -> 0.33886082 | I21: =Sheet1!J123 -> 0.29041237 | J21: =Sheet1!J124 -> 0.24685052
C28: =Sheet1!H125 -> 0.63363402 | D28: =Sheet1!H127 -> 0.53858892 | F28: =Sheet1!I125 -> 0.49832474 | G28: =Sheet1!I127 -> 0.42357603 | I28: =Sheet1!J125 -> 0.36301546 | J28: =Sheet1!J127 -> 0.30856314
C30: =Sheet1!H126 -> 0.31681701 | F30: =Sheet1!I126 -> 0.24916237 | I30: =Sheet1!J126 -> 0.18150773
